Workbook

Sheet Evaluation
A1: DocPilot — Evaluation Sheet
A2: Evaluate DocPilot answers across 50 questions. Mark each answer ✅ Correct, ⚠️ Partially Correct, or ❌ Incorrect.
A3: # | B3: Question | C3: Tool | D3: Confidence (DocPilot) | E3: Response Time (s) | F3: Correct? | G3: Notes | H3: Manual Search Time (s)
A4: 1 | B4: How do I build a funnel in Amplitude? | C4: Amplitude | D4: High | E4: 3.75 | F4: Correct | H4: 49.09
A5: 2 | B5: What is a behavioral cohort in Amplitude? | C5: Amplitude | D5: High | E5: 9.08 | F5: Correct | H5: 12.86
A6: 3 | B6: How do I track retention in Amplitude? | C6: Amplitude | D6: High | E6: 3.9 | F6: Correct | H6: 28.68
A7: 4 | B7: What is event segmentation? | C7: Amplitude | D7: Medium | E7: 4.23 | F7: Correct | H7: 15.78
A8: 5 | B8: How do I look up a specific user in Amplitude? | C8: Amplitude | D8: High | E8: 2.62 | F8: Correct | G8: Better than the docs. It actually summarized the exact steps | H8: 15.43
A9: 6 | B9: What is a conversion window in a funnel? | C9: Amplitude | D9: Low | E9: 4.19 | F9: Incorrect | G9: It couldn't find it in docs. The answer is a bit hidden - "Set your conversion window here, which is the maximum length of time allowed for a converting user to take between entering a funnel and completing it." I found it using Ctrl+F. | H9: 51.64
A10: 7 | B10: How do I exclude users from a funnel step? | C10: Amplitude | D10: Medium | E10: 3.1 | F10: Correct | G10: I couldn't find the answer manually and I gave up | H10: 69.07
A11: 8 | B11: What is the difference between this order and exact order in funnels? | C11: Amplitude | D11: Low | E11: 2.89 | F11: Correct | H11: 13.86
A12: 9 | B12: How do I compare two user segments? | C12: Amplitude | D12: Medium | E12: 2.95 | F12: Correct | G12: It simplified the explanation. The docs felt difficult to understand | H12: 71.21
A13: 10 | B13: What is N-day retention? | C13: Amplitude | D13: Low | E13: 4.21 | F13: Incorrect | G13: Couldn’t find in docs. In docs its named as this - N-Day LTV in retention analysis | H13: 13.75
A14: 11 | B14: How do I create a dashboard in Amplitude? | C14: Amplitude | D14: Medium | E14: 5.7 | F14: Partially Correct | G14: It only showed how to convert template to a dashboard whereas there is a separate article on creating dashboards which it didn’t link. | H14: 13.18
A15: 12 | B15: What is a Lifecycle chart? | C15: Amplitude | D15: Medium | E15: 3.65 | F15: Correct | H15: 7.81
A16: 13 | B16: What is Stickiness in Amplitude? | C16: Amplitude | D16: Medium | E16: 2.63 | F16: Correct | H16: 10.76
A17: 14 | B17: How do I filter events by user properties? | C17: Amplitude | D17: Medium | E17: 6.13 | F17: Incorrect | G17: DocPilot couldn’t find the answer. Even I was not able to find the answer manually. | H17: 89.74
A18: 15 | B18: What is a Journeys chart? | C18: Amplitude | D18: Medium | E18: 4.51 | F18: Correct | H18: 13.06
A19: 16 | B19: How do I add a segment to a chart? | C19: Amplitude | D19: Medium | E19: 5.56 | F19: Correct | H19: 10.46
A20: 17 | B20: What is account-level reporting? | C20: Amplitude | D20: Medium | E20: 3.21 | F20: Correct | H20: 8.71
A21: 18 | B21: How do I track revenue in Amplitude? | C21: Amplitude | D21: Medium | E21: 3.84 | F21: Correct | H21: 8.48
A22: 19 | B22: What is Compass in Amplitude? | C22: Amplitude | D22: Medium | E22: 2.35 | F22: Correct | H22: 50.37
A23: 20 | B23: How do I build a data table in Amplitude? | C23: Amplitude | D23: Medium | E23: 3.56 | F23: Incorrect | G23: DocPilot couldn’t find the answer. Even I was not able to find the answer manually. There is no data table but there is warehouse native data model. | H23: 21.6
A24: 21 | B24: How do I create a funnel in Mixpanel? | C24: Mixpanel | D24: High | E24: 2.51 | F24: Correct | G24: Manually searching got me more confused. DocPilot didn’t give me full answer but gave me the direction and links to the correct docs. | H24: 73.26
A25: 22 | B25: What is retention in Mixpanel? | C25: Mixpanel | D25: High | E25: 2.44 | F25: Correct | G25: Better than manual search, | H25: 30.55
A26: 23 | B26: How do I create a cohort in Mixpanel? | C26: Mixpanel | D26: High | E26: 4.99 | F26: Correct | H26: 9.16
A27: 24 | B27: What are custom events in Mixpanel? | C27: Mixpanel | D27: High | E27: 1.92 | F27: Correct | H27: 8.76
A28: 25 | B28: How do I use the Flows report in Mixpanel? | C28: Mixpanel | D28: High | E28: 5.04 | F28: Correct | G28: DocPilot was better. | H28: 35.48
A29: 26 | B29: What is the Insights report in Mixpanel? | C29: Mixpanel | D29: High | E29: 2.5 | F29: Correct | G29: Couldn't find it in docs. DocPilot gave a great answer and linked it directly to docs. | H29: 40.97
A30: 27 | B30: How do I analyze user paths in Mixpanel? | C30: Mixpanel | D30: High | E30: 4.28 | F30: Correct | G30: Couldn’t find in docs. Gave up | H30: 51.32
A31: 28 | B31: What is a saved report in Mixpanel? | C31: Mixpanel | D31: Medium | E31: 4.87 | F31: Incorrect | G31: DocPilot couldn’t find it. On manual search, I got something called Saved Query report. | H31: 8.55
A32: 29 | B32: How do I filter users in Mixpanel? | C32: Mixpanel | D32: High | E32: 6.72 | F32: Correct | H32: 25.83
A33: 30 | B33: What is a property in Mixpanel? | C33: Mixpanel | D33: Medium | E33: 6.93 | F33: Correct | H33: 3.35
A34: 31 | B34: How do I compare cohorts in Mixpanel? | C34: Mixpanel | D34: High | E34: 2.71 | F34: Correct | H34: 40.9
A35: 32 | B35: What is the difference between events and properties in Mixpanel? | C35: Mixpanel | D35: Medium | E35: 7.14 | F35: Correct | G35: There is no text regarding direct comparison in docs. But AI smartly gave the right difference | H35: 37.43
A36: 33 | B36: How do I measure feature adoption in Mixpanel? | C36: Mixpanel | D36: Medium | E36: 6.78 | F36: Correct | G36: Had better understanding only after reading the AI | H36: 13.07
A37: 34 | B37: What is a funnel conversion window in Mixpanel? | C37: Mixpanel | D37: Medium | E37: 4.33 | F37: Incorrect | G37: DocPilot couldn't find it. Manual search too gave very vague answer. "Mixpanel’s Funnels allows you to examine how end-users perform events in a series. Funnels calculate and display conversions from one event to another within a particular time window. " | H37: 35
A38: 35 | B38: How do I segment users by behavior in Mixpanel? | C38: Mixpanel | D38: Medium | E38: 3.11 | F38: Correct | G38: Manually couldn't find the answer. | H38: 82.09
A39: 36 | B39: What is a segment in Google Analytics? | C39: Google Analytics | D39: Medium | E39: 2.06 | F39: Correct | G39: Couldn't find it in docs. DocPilot gave a great answer and linked it directly to docs. | H39: 32.55
A40: 37 | B40: How do I track conversions in GA4? | C40: Google Analytics | D40: Medium | E40: 19.12 | F40: Correct | H40: 47.05
...

Sheet Summary
A1: DocPilot — Evaluation Summary
A2: Final results — 50 questions evaluated across Amplitude, Mixpanel, and Google Analytics
A3: Metric | B3: Target | C3: Actual
A4: OVERALL ACCURACY
A5: Total Questions Evaluated | C5: =COUNTA(Evaluation!B4:B53) -> 50
A6: ✅ Correct | C6: =COUNTIF(Evaluation!F4:F53,"Correct") -> 37
A7: ⚠️ Partially Correct | C7: =COUNTIF(Evaluation!F4:F53,"Partially Correct") -> 3
A8: ❌ Incorrect | C8: =COUNTIF(Evaluation!F4:F53,"Incorrect") -> 10
A9: Answer Accuracy % | C9: =COUNTIF(Evaluation!F4:F53,"Correct")/COUNTA(Evaluation!B4:B53)*100 -> 74
A10: Accuracy incl. Partial % | C10: =(COUNTIF(Evaluation!F4:F53,"Correct")+COUNTIF(Evaluation!F4:F53,"Partially Correct"))/COUNTA(Evaluation!B4:B53)*100 -> 80
A11: SPEED
A12: Avg Response Time (s) | C12: =AVERAGE(Evaluation!E4:E53) -> 4.3112
A13: Fastest Response (s) | C13: =MIN(Evaluation!E4:E53) -> 1.63
A14: Slowest Response (s) | C14: =MAX(Evaluation!E4:E53) -> 19.12
A15: Avg Manual Search Time (s) | C15: =AVERAGE(Evaluation!H4:H53) -> 27.2636
A16: Time Saved % | C16: =(C15-C12)/C15*100 -> 84.186975
A17: ACCURACY BY TOOL
A18: Amplitude — Questions | C18: =COUNTIF(Evaluation!C4:C53,"Amplitude") -> 20
A19: Amplitude — Correct | C19: =COUNTIFS(Evaluation!C4:C53,"Amplitude",Evaluation!F4:F53,"Correct") -> 15
A20: Amplitude — Accuracy % | C20: =COUNTIFS(Evaluation!C4:C53,"Amplitude",Evaluation!F4:F53,"Correct")/COUNTIF(Evaluation!C4:C53,"Amplitude")*100 -> 75
A21: Mixpanel — Questions | C21: =COUNTIF(Evaluation!C4:C53,"Mixpanel") -> 15
A22: Mixpanel — Correct | C22: =COUNTIFS(Evaluation!C4:C53,"Mixpanel",Evaluation!F4:F53,"Correct") -> 13
A23: Mixpanel — Accuracy % | C23: =COUNTIFS(Evaluation!C4:C53,"Mixpanel",Evaluation!F4:F53,"Correct")/COUNTIF(Evaluation!C4:C53,"Mixpanel")*100 -> 86.666667
A24: Google Analytics — Questions | C24: =COUNTIF(Evaluation!C4:C53,"Google Analytics") -> 15
A25: Google Analytics — Correct | C25: =COUNTIFS(Evaluation!C4:C53,"Google Analytics",Evaluation!F4:F53,"Correct") -> 9
A26: Google Analytics — Accuracy % | C26: =COUNTIFS(Evaluation!C4:C53,"Google Analytics",Evaluation!F4:F53,"Correct")/COUNTIF(Evaluation!C4:C53,"Google Analytics")*100 -> 60
A27: CONFIDENCE CALIBRATION
A28: High Confidence — n | C28: =COUNTIF(Evaluation!D4:D53,"High") -> 14
A29: High Confidence — Accuracy % | C29: =IFERROR(COUNTIFS(Evaluation!D4:D53,"High",Evaluation!F4:F53,"Correct")/COUNTIF(Evaluation!D4:D53,"High")*100,0) -> 100
A30: Medium Confidence — n | C30: =COUNTIF(Evaluation!D4:D53,"Medium") -> 33
A31: Medium Confidence — Accuracy % | C31: =IFERROR(COUNTIFS(Evaluation!D4:D53,"Medium",Evaluation!F4:F53,"Correct")/COUNTIF(Evaluation!D4:D53,"Medium")*100,0) -> 66.666667
A32: Low Confidence — n | C32: =COUNTIF(Evaluation!D4:D53,"Low") -> 3
A33: Low Confidence — Accuracy % | C33: =IFERROR(COUNTIFS(Evaluation!D4:D53,"Low",Evaluation!F4:F53,"Correct")/COUNTIF(Evaluation!D4:D53,"Low")*100,0) -> 33.333333

Sheet Instructions
A1: How to Use This Evaluation Sheet
A3: STEP 1 — Open DocPilot Go to your live URL: https://amplitude-copilot-frontend.vercel.app
A4: STEP 2 — Ask each question Copy each question from Column B in the Evaluation sheet and paste it into DocPilot.
A5: STEP 3 — Record Confidence Note the confidence badge shown (High / Medium / Low) → enter in Column D.
A6: STEP 4 — Record Response Time Note the ⏱ response time badge shown (e.g. 2.4s) → enter in Column E.
A7: STEP 5 — Verify the answer Check the answer against the official documentation. Mark Column F with one of: ✅ Correct ⚠️ Partially Correct ❌ Incorrect
A8: STEP 6 — Add notes If the answer was wrong or incomplete, note why in Column G.
A9: STEP 7 — Time manual search For 20 selected questions, time how long it takes to find the same answer manually in the docs. Enter in Column H.
A10: STEP 8 — Check Summary tab The Summary tab auto-calculates all metrics as you fill in the sheet.
A12: TIPS
A13: Correct (✅) Answer is accurate, complete, and matches the official documentation.
A14: Partially Correct (⚠️) Answer is on the right track but missing key details or has minor inaccuracies.
... A16: Manual Search Tip Start a stopwatch when you open the docs page, stop when you find the specific answer. Be honest.
